Workbook

Sheet WEST
A1: Продукт | B1: Январь | C1: Февраль | D1: Март | F1: Продажи Запад
A2: A | B2: 173 | C2: 1 | D2: 256
A3: A | B3: 208 | C3: 201 | D3: 224
A4: B | B4: 176 | C4: 33 | D4: 350
A5: B | B5: 190 | C5: 249 | D5: 215
A6: D | B6: 162 | C6: 74 | D6: 156
A7: D | B7: 90 | C7: 150 | D7: 170
A8: D | B8: 112 | C8: 284 | D8: 141
A9: G | B9: 154 | C9: 217 | D9: 113
A10: G | B10: 152 | C10: 200 | D10: 275
A11: G | B11: 277 | C11: 183 | D11: 372
A12: H | B12: 131 | C12: 71 | D12: 266
A13: F | B13: 294 | C13: 211 | D13: 249
... A24: D | B24: 173 | C24: 153 | D24: 270

Sheet Лист1
C1: Январь | D1: Февраль | E1: Март
B2: Урок4_Пример3_2 | C2: =WEST!$B$12 -> 131 | D2: =WEST!$C$12 -> 71 | E2: =WEST!$D$12 -> 266
A3: H | C3: =SUM(C2) -> 131 | D3: =SUM(D2) -> 71 | E3: =SUM(E2) -> 266
B4: Урок4_Пример3_2 | C4: =WEST!$B$13 -> 294 | D4: =WEST!$C$13 -> 211 | E4: =WEST!$D$13 -> 249
C5: =WEST!$B$14 -> 146 | D5: =WEST!$C$14 -> 125 | E5: =WEST!$D$14 -> 5
C6: =WEST!$B$16 -> 157 | D6: =WEST!$C$16 -> 241 | E6: =WEST!$D$16 -> 73
A7: F | C7: =SUM(C4:C6) -> 597 | D7: =SUM(D4:D6) -> 577 | E7: =SUM(E4:E6) -> 327
B8: Урок4_Пример3_1 | C8: =[1]EAST!$B$2 -> 205 | D8: =[1]EAST!$C$2 -> 263 | E8: =[1]EAST!$D$2 -> 20
C9: =[1]EAST!$B$8 -> 141 | D9: =[1]EAST!$C$8 -> 87 | E9: =[1]EAST!$D$8 -> 148
C10: =[1]EAST!$B$9 -> 2 | D10: =[1]EAST!$C$9 -> 15 | E10: =[1]EAST!$D$9 -> 135
C11: =[1]EAST!$B$10 -> 44 | D11: =[1]EAST!$C$10 -> 47 | E11: =[1]EAST!$D$10 -> 72
C12: =[1]EAST!$B$15 -> 84 | D12: =[1]EAST!$C$15 -> 103 | E12: =[1]EAST!$D$15 -> 134
B13: Урок4_Пример3_2 | C13: =WEST!$B$2 -> 173 | D13: =WEST!$C$2 -> 1 | E13: =WEST!$D$2 -> 256
C14: =WEST!$B$3 -> 208 | D14: =WEST!$C$3 -> 201 | E14: =WEST!$D$3 -> 224
C15: =WEST!$B$15 -> 115 | D15: =WEST!$C$15 -> 214 | E15: =WEST!$D$15 -> 141
C16: =WEST!$B$17 -> 125 | D16: =WEST!$C$17 -> 227 | E16: =WEST!$D$17 -> 135
C17: =WEST!$B$18 -> 314 | D17: =WEST!$C$18 -> 189 | E17: =WEST!$D$18 -> 180
A18: A | C18: =SUM(C8:C17) -> 1411 | D18: =SUM(D8:D17) -> 1347 | E18: =SUM(E8:E17) -> 1445
B19: Урок4_Пример3_1 | C19: =[1]EAST!$B$3 -> 164 | D19: =[1]EAST!$C$3 -> 17 | E19: =[1]EAST!$D$3 -> 146
C20: =[1]EAST!$B$11 -> 7 | D20: =[1]EAST!$C$11 -> 81 | E20: =[1]EAST!$D$11 -> 2
B21: Урок4_Пример3_2 | C21: =WEST!$B$4 -> 176 | D21: =WEST!$C$4 -> 33 | E21: =WEST!$D$4 -> 350
C22: =WEST!$B$5 -> 190 | D22: =WEST!$C$5 -> 249 | E22: =WEST!$D$5 -> 215
C23: =WEST!$B$22 -> 353 | D23: =WEST!$C$22 -> 151 | E23: =WEST!$D$22 -> 99
A24: B | C24: =SUM(C19:C23) -> 890 | D24: =SUM(D19:D23) -> 531 | E24: =SUM(E19:E23) -> 812
B25: Урок4_Пример3_1 | C25: =[1]EAST!$B$4 -> 278 | D25: =[1]EAST!$C$4 -> 177 | E25: =[1]EAST!$D$4 -> 179
B26: Урок4_Пример3_2 | C26: =WEST!$B$19 -> 189 | D26: =WEST!$C$19 -> 154 | E26: =WEST!$D$19 -> 101
C27: =WEST!$B$20 -> 313 | D27: =WEST!$C$20 -> 182 | E27: =WEST!$D$20 -> 68
C28: =WEST!$B$21 -> 389 | D28: =WEST!$C$21 -> 247 | E28: =WEST!$D$21 -> 257
C29: =WEST!$B$23 -> 62 | D29: =WEST!$C$23 -> 162 | E29: =WEST!$D$23 -> 238
A30: C | C30: =SUM(C25:C29) -> 1231 | D30: =SUM(D25:D29) -> 922 | E30: =SUM(E25:E29) -> 843
B31: Урок4_Пример3_1 | C31: =[1]EAST!$B$5 -> 156 | D31: =[1]EAST!$C$5 -> 214 | E31: =[1]EAST!$D$5 -> 240
C32: =[1]EAST!$B$6 -> 72 | D32: =[1]EAST!$C$6 -> 134 | E32: =[1]EAST!$D$6 -> 48
C33: =[1]EAST!$B$7 -> 7 | D33: =[1]EAST!$C$7 -> 256 | E33: =[1]EAST!$D$7 -> 104
C34: =[1]EAST!$B$17 -> -5 | D34: =[1]EAST!$C$17 -> 159 | E34: =[1]EAST!$D$17 -> 70
B35: Урок4_Пример3_2 | C35: =WEST!$B$6 -> 162 | D35: =WEST!$C$6 -> 74 | E35: =WEST!$D$6 -> 156
C36: =WEST!$B$7 -> 90 | D36: =WEST!$C$7 -> 150 | E36: =WEST!$D$7 -> 170
C37: =WEST!$B$8 -> 112 | D37: =WEST!$C$8 -> 284 | E37: =WEST!$D$8 -> 141
C38: =WEST!$B$24 -> 173 | D38: =WEST!$C$24 -> 153 | E38: =WEST!$D$24 -> 270
A39: D | C39: =SUM(C31:C38) -> 767 | D39: =SUM(D31:D38) -> 1424 | E39: =SUM(E31:E38) -> 1199
B40: Урок4_Пример3_1 | C40: =[1]EAST!$B$12 -> 25 | D40: =[1]EAST!$C$12 -> 120 | E40: =[1]EAST!$D$12 -> 171
...

Sheet Лист2
C1: Январь | D1: Февраль | E1: Март
B2: Урок4_Пример3_2 | C2: =WEST!$B$12 -> 131 | D2: =WEST!$C$12 -> 71 | E2: =WEST!$D$12 -> 266
A3: H | C3: =SUM(C2) -> 131 | D3: =SUM(D2) -> 71 | E3: =SUM(E2) -> 266
B4: Урок4_Пример3_2 | C4: =WEST!$B$13 -> 294 | D4: =WEST!$C$13 -> 211 | E4: =WEST!$D$13 -> 249
C5: =WEST!$B$14 -> 146 | D5: =WEST!$C$14 -> 125 | E5: =WEST!$D$14 -> 5
C6: =WEST!$B$16 -> 157 | D6: =WEST!$C$16 -> 241 | E6: =WEST!$D$16 -> 73
A7: F | C7: =SUM(C4:C6) -> 597 | D7: =SUM(D4:D6) -> 577 | E7: =SUM(E4:E6) -> 327
B8: Урок4_Пример3_1 | C8: =[1]EAST!$B$2 -> 205 | D8: =[1]EAST!$C$2 -> 263 | E8: =[1]EAST!$D$2 -> 20
C9: =[1]EAST!$B$8 -> 141 | D9: =[1]EAST!$C$8 -> 87 | E9: =[1]EAST!$D$8 -> 148
C10: =[1]EAST!$B$9 -> 2 | D10: =[1]EAST!$C$9 -> 15 | E10: =[1]EAST!$D$9 -> 135
C11: =[1]EAST!$B$10 -> 44 | D11: =[1]EAST!$C$10 -> 47 | E11: =[1]EAST!$D$10 -> 72
C12: =[1]EAST!$B$15 -> 84 | D12: =[1]EAST!$C$15 -> 103 | E12: =[1]EAST!$D$15 -> 134
B13: Урок4_Пример3_2 | C13: =WEST!$B$2 -> 173 | D13: =WEST!$C$2 -> 1 | E13: =WEST!$D$2 -> 256
C14: =WEST!$B$3 -> 208 | D14: =WEST!$C$3 -> 201 | E14: =WEST!$D$3 -> 224
C15: =WEST!$B$15 -> 115 | D15: =WEST!$C$15 -> 214 | E15: =WEST!$D$15 -> 141
C16: =WEST!$B$17 -> 125 | D16: =WEST!$C$17 -> 227 | E16: =WEST!$D$17 -> 135
C17: =WEST!$B$18 -> 314 | D17: =WEST!$C$18 -> 189 | E17: =WEST!$D$18 -> 180
A18: A | C18: =SUM(C8:C17) -> 1411 | D18: =SUM(D8:D17) -> 1347 | E18: =SUM(E8:E17) -> 1445
B19: Урок4_Пример3_1 | C19: =[1]EAST!$B$3 -> 164 | D19: =[1]EAST!$C$3 -> 17 | E19: =[1]EAST!$D$3 -> 146
C20: =[1]EAST!$B$11 -> 7 | D20: =[1]EAST!$C$11 -> 81 | E20: =[1]EAST!$D$11 -> 2
B21: Урок4_Пример3_2 | C21: =WEST!$B$4 -> 176 | D21: =WEST!$C$4 -> 33 | E21: =WEST!$D$4 -> 350
C22: =WEST!$B$5 -> 190 | D22: =WEST!$C$5 -> 249 | E22: =WEST!$D$5 -> 215
C23: =WEST!$B$22 -> 353 | D23: =WEST!$C$22 -> 151 | E23: =WEST!$D$22 -> 99
A24: B | C24: =SUM(C19:C23) -> 890 | D24: =SUM(D19:D23) -> 531 | E24: =SUM(E19:E23) -> 812
B25: Урок4_Пример3_1 | C25: =[1]EAST!$B$4 -> 278 | D25: =[1]EAST!$C$4 -> 177 | E25: =[1]EAST!$D$4 -> 179
B26: Урок4_Пример3_2 | C26: =WEST!$B$19 -> 189 | D26: =WEST!$C$19 -> 154 | E26: =WEST!$D$19 -> 101
C27: =WEST!$B$20 -> 313 | D27: =WEST!$C$20 -> 182 | E27: =WEST!$D$20 -> 68
C28: =WEST!$B$21 -> 389 | D28: =WEST!$C$21 -> 247 | E28: =WEST!$D$21 -> 257
C29: =WEST!$B$23 -> 62 | D29: =WEST!$C$23 -> 162 | E29: =WEST!$D$23 -> 238
A30: C | C30: =SUM(C25:C29) -> 1231 | D30: =SUM(D25:D29) -> 922 | E30: =SUM(E25:E29) -> 843
B31: Урок4_Пример3_1 | C31: =[1]EAST!$B$5 -> 156 | D31: =[1]EAST!$C$5 -> 214 | E31: =[1]EAST!$D$5 -> 240
C32: =[1]EAST!$B$6 -> 72 | D32: =[1]EAST!$C$6 -> 134 | E32: =[1]EAST!$D$6 -> 48
C33: =[1]EAST!$B$7 -> 7 | D33: =[1]EAST!$C$7 -> 256 | E33: =[1]EAST!$D$7 -> 104
C34: =[1]EAST!$B$17 -> -5 | D34: =[1]EAST!$C$17 -> 159 | E34: =[1]EAST!$D$17 -> 70
B35: Урок4_Пример3_2 | C35: =WEST!$B$6 -> 162 | D35: =WEST!$C$6 -> 74 | E35: =WEST!$D$6 -> 156
C36: =WEST!$B$7 -> 90 | D36: =WEST!$C$7 -> 150 | E36: =WEST!$D$7 -> 170
C37: =WEST!$B$8 -> 112 | D37: =WEST!$C$8 -> 284 | E37: =WEST!$D$8 -> 141
C38: =WEST!$B$24 -> 173 | D38: =WEST!$C$24 -> 153 | E38: =WEST!$D$24 -> 270
A39: D | C39: =SUM(C31:C38) -> 767 | D39: =SUM(D31:D38) -> 1424 | E39: =SUM(E31:E38) -> 1199
B40: Урок4_Пример3_1 | C40: =[1]EAST!$B$12 -> 25 | D40: =[1]EAST!$C$12 -> 120 | E40: =[1]EAST!$D$12 -> 171
...
