Workbook

Sheet WEST
A1: Продукт | B1: Январь | C1: Февраль | D1: Март | F1: Продажи Запад
A2: A | B2: 173 | C2: 1 | D2: 256
A3: A | B3: 208 | C3: 201 | D3: 224
A4: B | B4: 176 | C4: 33 | D4: 350
A5: B | B5: 190 | C5: 249 | D5: 215
A6: D | B6: 162 | C6: 74 | D6: 156
A7: D | B7: 90 | C7: 150 | D7: 170
A8: D | B8: 112 | C8: 284 | D8: 141
A9: G | B9: 154 | C9: 217 | D9: 113
A10: G | B10: 152 | C10: 200 | D10: 275
A11: G | B11: 277 | C11: 183 | D11: 372
A12: H | B12: 131 | C12: 71 | D12: 266
A13: F | B13: 294 | C13: 211 | D13: 249
... A24: D | B24: 173 | C24: 153 | D24: 270

Sheet Лист4
D1: Январь | E1: Февраль | F1: Март
B3: Семинар5_Задание2-2 | D3: =WEST!$B$12 -> 131 | E3: =WEST!$C$12 -> 71 | F3: =WEST!$D$12 -> 266
A4: H | D4: =MAX(D3) -> 131 | E4: =MAX(E3) -> 71 | F4: =MAX(F3) -> 266
B8: Семинар5_Задание2-2 | D8: =WEST!$B$13 -> 294 | E8: =WEST!$C$13 -> 211 | F8: =WEST!$D$13 -> 249
D9: =WEST!$B$14 -> 146 | E9: =WEST!$C$14 -> 125 | F9: =WEST!$D$14 -> 5
D10: =WEST!$B$16 -> 157 | E10: =WEST!$C$16 -> 241 | F10: =WEST!$D$16 -> 73
A11: F | D11: =MAX(D8:D10) -> 294 | E11: =MAX(E8:E10) -> 241 | F11: =MAX(F8:F10) -> 249
B22: Семинар5_Задание2-1 | D22: =[1]EAST!$B$2 -> 205 | E22: =[1]EAST!$C$2 -> 263 | F22: =[1]EAST!$D$2 -> 20
D23: =[1]EAST!$B$8 -> 141 | E23: =[1]EAST!$C$8 -> 87 | F23: =[1]EAST!$D$8 -> 148
D24: =[1]EAST!$B$9 -> 2 | E24: =[1]EAST!$C$9 -> 15 | F24: =[1]EAST!$D$9 -> 135
D25: =[1]EAST!$B$10 -> 44 | E25: =[1]EAST!$C$10 -> 47 | F25: =[1]EAST!$D$10 -> 72
D26: =[1]EAST!$B$15 -> 84 | E26: =[1]EAST!$C$15 -> 103 | F26: =[1]EAST!$D$15 -> 134
B27: Семинар5_Задание2-2 | D27: =WEST!$B$2 -> 173 | E27: =WEST!$C$2 -> 1 | F27: =WEST!$D$2 -> 256
D28: =WEST!$B$3 -> 208 | E28: =WEST!$C$3 -> 201 | F28: =WEST!$D$3 -> 224
D29: =WEST!$B$15 -> 115 | E29: =WEST!$C$15 -> 214 | F29: =WEST!$D$15 -> 141
D30: =WEST!$B$17 -> 125 | E30: =WEST!$C$17 -> 227 | F30: =WEST!$D$17 -> 135
D31: =WEST!$B$18 -> 314 | E31: =WEST!$C$18 -> 189 | F31: =WEST!$D$18 -> 180
A32: A | D32: =MAX(D22:D31) -> 314 | E32: =MAX(E22:E31) -> 263 | F32: =MAX(F22:F31) -> 256
B38: Семинар5_Задание2-1 | D38: =[1]EAST!$B$3 -> 164 | E38: =[1]EAST!$C$3 -> 17 | F38: =[1]EAST!$D$3 -> 146
D39: =[1]EAST!$B$11 -> 7 | E39: =[1]EAST!$C$11 -> 81 | F39: =[1]EAST!$D$11 -> 2
B40: Семинар5_Задание2-2 | D40: =WEST!$B$4 -> 176 | E40: =WEST!$C$4 -> 33 | F40: =WEST!$D$4 -> 350
D41: =WEST!$B$5 -> 190 | E41: =WEST!$C$5 -> 249 | F41: =WEST!$D$5 -> 215
D42: =WEST!$B$22 -> 353 | E42: =WEST!$C$22 -> 151 | F42: =WEST!$D$22 -> 99
A43: B | D43: =MAX(D38:D42) -> 353 | E43: =MAX(E38:E42) -> 249 | F43: =MAX(F38:F42) -> 350
B49: Семинар5_Задание2-1 | D49: =[1]EAST!$B$4 -> 278 | E49: =[1]EAST!$C$4 -> 177 | F49: =[1]EAST!$D$4 -> 179
B50: Семинар5_Задание2-2 | D50: =WEST!$B$19 -> 189 | E50: =WEST!$C$19 -> 154 | F50: =WEST!$D$19 -> 101
D51: =WEST!$B$20 -> 313 | E51: =WEST!$C$20 -> 182 | F51: =WEST!$D$20 -> 68
D52: =WEST!$B$21 -> 389 | E52: =WEST!$C$21 -> 247 | F52: =WEST!$D$21 -> 257
D53: =WEST!$B$23 -> 62 | E53: =WEST!$C$23 -> 162 | F53: =WEST!$D$23 -> 238
A54: C | D54: =MAX(D49:D53) -> 389 | E54: =MAX(E49:E53) -> 247 | F54: =MAX(F49:F53) -> 257
B63: Семинар5_Задание2-1 | D63: =[1]EAST!$B$5 -> 156 | E63: =[1]EAST!$C$5 -> 214 | F63: =[1]EAST!$D$5 -> 240
D64: =[1]EAST!$B$6 -> 72 | E64: =[1]EAST!$C$6 -> 134 | F64: =[1]EAST!$D$6 -> 48
D65: =[1]EAST!$B$7 -> 7 | E65: =[1]EAST!$C$7 -> 256 | F65: =[1]EAST!$D$7 -> 104
D66: =[1]EAST!$B$17 -> -5 | E66: =[1]EAST!$C$17 -> 159 | F66: =[1]EAST!$D$17 -> 70
B67: Семинар5_Задание2-2 | D67: =WEST!$B$6 -> 162 | E67: =WEST!$C$6 -> 74 | F67: =WEST!$D$6 -> 156
D68: =WEST!$B$7 -> 90 | E68: =WEST!$C$7 -> 150 | F68: =WEST!$D$7 -> 170
D69: =WEST!$B$8 -> 112 | E69: =WEST!$C$8 -> 284 | F69: =WEST!$D$8 -> 141
D70: =WEST!$B$24 -> 173 | E70: =WEST!$C$24 -> 153 | F70: =WEST!$D$24 -> 270
A71: D | D71: =MAX(D63:D70) -> 173 | E71: =MAX(E63:E70) -> 284 | F71: =MAX(F63:F70) -> 270
B76: Семинар5_Задание2-1 | D76: =[1]EAST!$B$12 -> 25 | E76: =[1]EAST!$C$12 -> 120 | F76: =[1]EAST!$D$12 -> 171
...
